Workbook

Sheet README
A1: YKP3089C017 — Data Review Package
A2: Version | B2: 1.0 — 02-Oct-2026
A3: Prepared by | B3: Tracy Adu
A4: What this shows | B4: A full offline data review cycle for a mock epilepsy trial, run without an EDC: programmed edit checks in Python, a discrepancy listing, queries to sites, corrections with an audit trail, and a re-run that confirms the data is clean.
A5: Why offline | B5: Without an EDC, hard checks can't block bad entries at the point of data entry. Every check runs after the fact, and a person reviews every hit. That is the gap an EDC closes.
A6: Disclaimer | B6: Synthetic data. Site responses, dates and turnaround times are simulated to show a realistic review cycle. Not affiliated with SK Life Science.
A8: WORKFLOW
A9: 1. Run checks | B9: run_edit_checks.py runs all 19 programmed checks and the review listings against the v1.0 data and writes the Discrepancy Listing.
A10: 2. Review hits | B10: Each hit is reviewed before any query goes out. Two pairs of hits shared a root cause, so each pair became one query; the site isn't asked the same thing twice. Screen failures and the dose-reduction listing were handled as listing reviews, with no query.
A11: 3. Query and resolve | B11: Queries were answered by sites, verified by data management, and closed. One answer didn't resolve the issue, so the query was re-issued.
A12: 4. Correct and audit | B12: Every data change is logged with old value, new value, who, when, and the query behind it (21 CFR Part 11-style audit trail). Corrected data = v1.1.
A13: 5. Re-run | B13: Checks re-run on v1.1. The only remaining hits were already reviewed and closed (true values confirmed by the site, one escalation, listing items).
A15: KEY RESULTS (live)
A16: Discrepancy listing hits | B16: =Metrics!B4 -> 25
A17: Queries issued | B17: =Metrics!B5 -> 20
A18: Queries closed | B18: =Metrics!B6 -> 20
A19: Data changes (audit trail) | B19: =Metrics!B10 -> 21
A20: New discrepancies after re-run | B20: =Metrics!B67 -> 0

Sheet Metrics
A1: YKP3089C017 — Data Review Metrics (as of 02-Oct-2026)
A3: Volume | B3: Count
A4: Discrepancy listing hits (v1.0 data) | B4: =COUNTA('Discrepancy Listing'!A:A)-1 -> 25
A5: Queries issued | B5: =COUNTA('Query Log'!A:A)-1 -> 20
A6: Closed | B6: =COUNTIF('Query Log'!P:P,"Closed") -> 20
A7: Open | B7: =COUNTIF('Query Log'!P:P,"Open") -> 0
A8: Re-queried (first answer didn't resolve it) | B8: =COUNTIF('Query Log'!M:M,"Y") -> 1
A9: Listing review log entries (no query sent) | B9: =COUNTA('Listing Review'!A:A)-1 -> 6
A10: Data changes in audit trail | B10: =COUNTA('Audit Trail'!A:A)-1 -> 21
A12: Resolution Type | B12: Queries | C12: % of Queries
A13: Data corrected | B13: =COUNTIF('Query Log'!Q:Q,"Data corrected") -> 16 | C13: =B13/$B$5 -> 0.8
A14: Confirmed correct | B14: =COUNTIF('Query Log'!Q:Q,"Confirmed correct") -> 3 | C14: =B14/$B$5 -> 0.15
A15: Escalated | B15: =COUNTIF('Query Log'!Q:Q,"Escalated") -> 1 | C15: =B15/$B$5 -> 0.05
A17: Form | B17: Queries | C17: % of Queries
A18: DM — Demographics | B18: =COUNTIF('Query Log'!D:D,"DM") -> 5 | C18: =B18/$B$5 -> 0.25
A19: SZ — Seizure Diary | B19: =COUNTIF('Query Log'!D:D,"SZ") -> 8 | C19: =B19/$B$5 -> 0.4
A20: AE — Adverse Events | B20: =COUNTIF('Query Log'!D:D,"AE") -> 7 | C20: =B20/$B$5 -> 0.35
A22: Check Severity | B22: Queries
A23: Hard | B23: =COUNTIF('Query Log'!H:H,"Hard") -> 7
A24: Soft | B24: =COUNTIF('Query Log'!H:H,"Soft") -> 11
A25: Hard + Soft (one query, two checks) | B25: =COUNTIF('Query Log'!H:H,"Hard + Soft") -> 2
A27: Site | B27: Queries | C27: Avg Days to Response | D27: Max Days to Response | E27: Answered ≤ 7 Days
A28: Site 001 | B28: =COUNTIF('Query Log'!B:B,"001") -> 6 | C28: =AVERAGEIF('Query Log'!B:B,"001",'Query Log'!R:R) -> 3.5 | D28: =_xlfn.MAXIFS('Query Log'!R:R,'Query Log'!B:B,"001") -> 5 | E28: =COUNTIFS('Query Log'!B:B,"001",'Query Log'!R:R,"<=7")/B28 -> 1
A29: Site 002 | B29: =COUNTIF('Query Log'!B:B,"002") -> 7 | C29: =AVERAGEIF('Query Log'!B:B,"002",'Query Log'!R:R) -> 6.2857143 | D29: =_xlfn.MAXIFS('Query Log'!R:R,'Query Log'!B:B,"002") -> 13 | E29: =COUNTIFS('Query Log'!B:B,"002",'Query Log'!R:R,"<=7")/B29 -> 0.85714286
A30: Site 003 | B30: =COUNTIF('Query Log'!B:B,"003") -> 7 | C30: =AVERAGEIF('Query Log'!B:B,"003",'Query Log'!R:R) -> 6.5714286 | D30: =_xlfn.MAXIFS('Query Log'!R:R,'Query Log'!B:B,"003") -> 9 | E30: =COUNTIFS('Query Log'!B:B,"003",'Query Log'!R:R,"<=7")/B30 -> 0.71428571
A32: Turnaround (all queries) | B32: Value
A33: Average days to site response | B33: =AVERAGE('Query Log'!R:R) -> 5.55
A34: Average days from open to close | B34: =AVERAGE('Query Log'!S:S) -> 7.1
A35: Answered within 7 days | B35: =COUNTIF('Query Log'!R:R,"<=7")/COUNT('Query Log'!R:R) -> 0.85
A37: Query Rate | B37: Value
A38: Data points entered (v1.0) | B38: 31841
A39: Queries per 1,000 data points | B39: =B5/B38*1000 -> 0.62812098
A40: Data points = non-blank entered fields (derived and pre-populated fields excluded), counted by script from v1.0. Blue = hardcoded input.
A42: Check ID | B42: Queries Raised
A43: DM01 | B43: =COUNTIF('Query Log'!G:G,"*DM01*") -> 1
A44: DM02 | B44: =COUNTIF('Query Log'!G:G,"*DM02*") -> 1
A45: DM03 | B45: =COUNTIF('Query Log'!G:G,"*DM03*") -> 1
A46: DM04 | B46: =COUNTIF('Query Log'!G:G,"*DM04*") -> 0
A47: DM05 | B47: =COUNTIF('Query Log'!G:G,"*DM05*") -> 1
A48: DM06 | B48: =COUNTIF('Query Log'!G:G,"*DM06*") -> 1
...

Sheet Discrepancy Listing
A1: Check ID | B1: Hard / Soft | C1: SUBJID | D1: SITEID | E1: Form | F1: Record | G1: Field(s) | H1: Value Found | I1: Query Text | J1: Action Type
A2: AE01 | B2: Hard | C2: 01001001 | D2: 001 | E2: AE | F2: AESPID 1: Headache | G2: AESTDAT, AEENDAT | H2: 04-APR-2026 / 06-APR-2025 | I2: AE end date is before the start date. Please verify both dates against source. | J2: Query
A3: AE02 | B3: Hard | C3: 01002001 | D3: 002 | E3: AE | F3: AESPID 2: Fatigue | G3: AEONGO, AEENDAT | H3: AEONGO Y; end 24-MAY-2026 | I3: The ongoing status, end date and outcome for this event are inconsistent. Please review. | J3: Query
A4: AE02 | B4: Soft | C4: 01002001 | D4: 002 | E4: AE | F4: AESPID 2: Fatigue | G4: AEONGO, AEOUT | H4: AEONGO Y; outcome RECOVERED/RESOLVED | I4: The ongoing status, end date and outcome for this event are inconsistent. Please review. | J4: Query
A5: AE03 | B5: Hard | C5: 01002005 | D5: 002 | E5: AE | F5: AESPID 1: Pneumonia | G5: AESER, criteria | H5: AESER Y | I5: This event's seriousness and seriousness criteria are inconsistent. Please review. | J5: Query
A6: AE04 | B6: Soft | C6: 01003001 | D6: 003 | E6: AE | F6: AESPID 1: Headache | G6: AESTDAT | H6: 5 days before consent | I6: AE start date is before informed consent. Please verify the start date, or confirm whether this condition should be recorded as medical history. | J6: Query
A7: AE05 | B7: Soft | C7: 01001003 | D7: 001 | E7: AE | F7: AESPID 1: Nausea | G7: AESTDAT, AEREL | H7: Before first dose; AEREL POSSIBLE | I7: This event started before the first dose of study drug, and relationship is recorded as POSSIBLE. Please review the relationship assessment per protocol section 10.3. | J7: Query
A8: AE06 | B8: Soft | C8: 01002004 | D8: 002 | E8: AE | F8: AESPID 3: Increased seizure frequency | G8: AETERM | H8: Increased seizure frequency | I8: Seizures are normally recorded in the seizure diary. Please confirm this event meets the AE definition in protocol section 10.4.1 (a measurable increase in frequency or duration, or a pattern distinguishable from the subject's usual seizures). | J8: Query
A9: AE06 | B9: Soft | C9: 01003002 | D9: 003 | E9: AE | F9: AESPID 3: Seizure | G9: AETERM | H9: Seizure | I9: Seizures are normally recorded in the seizure diary. Please confirm this event meets the AE definition in protocol section 10.4.1 (a measurable increase in frequency or duration, or a pattern distinguishable from the subject's usual seizures). | J9: Query
A10: DM01 | B10: Soft | C10: 01002006 | D10: 002 | E10: DM | F10: Demographics | G10: AGE | H10: 73 | I10: Age at consent (73) is outside the protocol range of 18-70 years (Inclusion 1). Please verify date of birth and date of consent against source. | J10: Query
A11: DM02 | B11: Hard | C11: 01003005 | D11: 002 | E11: DM | F11: Demographics | G11: SUBJID, SITEID | H11: SITEID 002 | I11: Screening number must be 8 digits, with digits 3-5 matching the site number. Please correct. | J11: Query
A12: DM03 | B12: Hard | C12: 01001002 | D12: 001 | E12: DM | F12: Demographics | G12: SEX, CHILDPOT | H12: SEX F, CHILDPOT (blank) | I12: Childbearing potential must be answered for female subjects and left blank for male subjects. Please review. | J12: Query
... A26: SZ06 | B26: Soft | C26: 01003006 | D26: 003 | E26: SZ | F26: Baseline period | G26: SZCOUNT (derived) | H26: weeks 1-4 = 2 < 3 | I26: Per the diary data entered, the subject does not appear to meet the baseline seizure criteria (Inclusion 6): weeks 1-4 = 2 < 3. Please verify the diary entries against source. | J26: Query

Sheet Query Log
A1: Query ID | B1: SITEID | C1: SUBJID | D1: Form | E1: Record | F1: Field(s) | G1: Check ID(s) | H1: Hard / Soft | I1: Query Text | J1: Date Opened | K1: Site Response | L1: Date Answered | M1: Re-queried? | N1: DM Review / Action | O1: Date Closed | P1: Status | Q1: Resolution Type | R1: Days to Site Response | S1: Days Open
A2: QRY-001 | B2: 001 | C2: 01001002 | D2: DM | E2: Demographics | F2: CHILDPOT | G2: DM03 | H2: Hard | I2: Childbearing potential must be answered for female subjects and left blank for male subjects. Please review. | J2: 46048 | K2: Subject is post-menopausal per medical history documented at Visit 1. Entered N. | L2: 46051 | M2: N | N2: Verified. Closed. | O2: 46053 | P2: Closed | Q2: Data corrected | R2: =L2-J2 -> 3 | S2: =O2-J2 -> 5
A3: QRY-002 | B3: 003 | C3: 01003005 | D3: DM | E3: Demographics | F3: SITEID | G3: DM02 | H3: Hard | I3: Screening number must be 8 digits, with digits 3-5 matching the site number. Please correct. | J3: 46055 | K3: Coordinator covers sites 002 and 003 and selected the wrong site. Site number corrected to 003. | L3: 46060 | M3: N | N3: Verified. Note: a live EDC would have blocked this entry. Closed. | O3: 46061 | P3: Closed | Q3: Data corrected | R3: =L3-J3 -> 5 | S3: =O3-J3 -> 6
A4: QRY-003 | B4: 003 | C4: 01003001 | D4: AE | E4: AESPID 1: Headache | F4: Whole record | G4: AE04 | H4: Soft | I4: AE start date is before informed consent. Please verify the start date, or confirm whether this condition should be recorded as medical history. | J4: 46062 | K4: Headache began before consent and did not worsen afterward. Recorded in medical history; AE deleted per investigator. | L4: 46071 | M4: N | N4: Verified deletion and medical history entry. Closed. | O4: 46073 | P4: Closed | Q4: Data corrected | R4: =L4-J4 -> 9 | S4: =O4-J4 -> 11
A5: QRY-004 | B5: 002 | C5: 01002006 | D5: DM | E5: Demographics | F5: BRTHDAT (AGE) | G5: DM01 | H5: Soft | I5: Age at consent (73) is outside the protocol range of 18-70 years (Inclusion 1). Please verify date of birth and date of consent against source. | J5: 46069 | K5: Verified against the copy of the subject's driver's license in the subject file. Birth year was mistyped; DOB corrected to 28-OCT-1982. | L5: 46075 | M5: N | N5: Correction verified; derived age now 43. Closed. | O5: 46077 | P5: Closed | Q5: Data corrected | R5: =L5-J5 -> 6 | S5: =O5-J5 -> 8
A6: QRY-005 | B6: 002 | C6: 01002002 | D6: DM | E6: Demographics | F6: RANDDAT | G6: DM05 | H6: Soft | I6: Randomization date is 61 days after informed consent. The protocol specifies an 8-week baseline (Visit 1, Day -56 to Visit 3, Day 1, +/-2 days). Please verify both dates. | J6: 46104 | K6: Both dates verified against visit notes. Visit 3 was delayed because the subject was out of state for a family emergency. Out-of-window visit reported to the CRA as a protocol deviation. | L6: 46110 | M6: N | N6: Dates confirmed correct; no data change. Deviation noted. Closed. | O6: 46111 | P6: Closed | Q6: Confirmed correct | R6: =L6-J6 -> 6 | S6: =O6-J6 -> 7
A7: QRY-006 | B7: 001 | C7: 01001003 | D7: AE | E7: AESPID 1: Nausea | F7: AEREL | G7: AE05 | H7: Soft | I7: This event started before the first dose of study drug, and relationship is recorded as POSSIBLE. Please review the relationship assessment per protocol section 10.3. | J7: 46111 | K7: Investigator reviewed: nausea started during baseline, before any study drug. Relationship changed to Unrelated. | L7: 46115 | M7: N | N7: Verified. Closed. | O7: 46116 | P7: Closed | Q7: Data corrected | R7: =L7-J7 -> 4 | S7: =O7-J7 -> 5
A8: QRY-007 | B8: 003 | C8: 01003002 | D8: DM | E8: Demographics | F8: EXSTDAT | G8: DM06 | H8: Soft | I8: Date of first dose is 3 day(s) after randomization. Per protocol, dosing begins the morning after randomization, or on Day 1 if given at the site. Please verify. | J8: 46111 | K8: Date was copied from the dosing card label. Subject's dosing log shows the first dose the morning after randomization. Corrected. | L8: 46116 | M8: N | N8: Correction verified against the expected Day 2 first dose. Closed. | O8: 46117 | P8: Closed | Q8: Data corrected | R8: =L8-J8 -> 5 | S8: =O8-J8 -> 6
A9: QRY-008 | B9: 003 | C9: 01003001 | D9: SZ | E9: SZDAT 29-MAR-2026 | F9: Whole record | G9: SZ02 | H9: Hard | I9: A diary record already exists for this date. Please remove the duplicate or correct the date. | J9: 46125 | K9: Diary page was entered twice after a system time-out. Duplicate deleted. | L9: 46134 | M9: N | N9: Verified one record remains. Closed. | O9: 46135 | P9: Closed | Q9: Data corrected | R9: =L9-J9 -> 9 | S9: =O9-J9 -> 10
A10: QRY-009 | B10: 003 | C10: 01003006 | D10: SZ | E10: Baseline period | F10: SZCOUNT (derived) | G10: SZ06 | H10: Soft | I10: Per the diary data entered, the subject does not appear to meet the baseline seizure criteria (Inclusion 6): weeks 1-4 = 2 < 3. Please verify the diary entries against source. | J10: 46125 | K10: Diary entries re-verified against source. Data are correct: 2 qualifying seizures in weeks 1-4 of baseline. | L10: 46130 | M10: N | N10: Data confirmed. Escalated to CRA and medical monitor as a potential eligibility deviation (Inclusion 6); the subject's continuation is a sponsor decision outside data review. Closed. | O10: 46134 | P10: Closed | Q10: Escalated | R10: =L10-J10 -> 5 | S10: =O10-J10 -> 9
A11: QRY-010 | B11: 001 | C11: 01001001 | D11: AE | E11: AESPID 1: Headache | F11: AEENDAT | G11: AE01 | H11: Hard | I11: AE end date is before the start date. Please verify both dates against source. | J11: 46139 | K11: End date year was mistyped. Correct end date is 06-APR-2026. Corrected. | L11: 46144 | M11: N | N11: Verified. Closed. | O11: 46146 | P11: Closed | Q11: Data corrected | R11: =L11-J11 -> 5 | S11: =O11-J11 -> 7
A12: QRY-011 | B12: 002 | C12: 01002004 | D12: SZ | E12: SZDAT 21-APR-2026 | F12: SZDIARY, counts | G12: SZ01 | H12: Hard | I12: Diary data recorded for this day is N, but the seizure counts are entered. Please review against the diary page. | J12: 46139 | K12: [04-MAY-2026] Subject reported no seizures that day. [10-MAY-2026] Diary page for this date is blank. Zeros removed; 'diary data recorded' remains No. | L12: 46152 | M12: Y | N12: Re-queried 05-MAY-2026: If the subject had no seizures, 'diary data recorded' should be Yes with counts of 0. If the diary page is blank, counts should be blank. Please confirm which applies against the diary page. Verified. Day is now excluded from the seizure-rate denominator instead of counting as seizure-free. Closed. | O12: 46154 | P12: Closed | Q12: Data corrected | R12: =L12-J12 -> 13 | S12: =O12-J12 -> 15
A13: QRY-012 | B13: 002 | C13: 01002001 | D13: AE | E13: AESPID 2: Fatigue | F13: AEONGO | G13: AE02 | H13: Hard + Soft | I13: The ongoing status, end date and outcome for this event are inconsistent. Please review. | J13: 46188 | K13: Event resolved on 24-MAY-2026; 'ongoing' was never updated. Changed to No. | L13: 46195 | M13: N | N13: Both AE02 hits (end date and outcome) cleared by one change. Closed. | O13: 46196 | P13: Closed | Q13: Data corrected | R13: =L13-J13 -> 7 | S13: =O13-J13 -> 8
... A21: QRY-020 | B21: 002 | C21: 01002007 | D21: SZ | E21: SZDAT 11-OCT-2026 (should be 11-SEP-2026) | F21: SZDAT | G21: SZ03, SZ05 | H21: Hard + Soft | I21: Diary date 11-OCT-2026 is after the visit at which the diary was returned (16-SEP-2026), and no diary record exists for 11-SEP-2026. Please verify the date against the diary. | J21: 46286 | K21: Month was mistyped. Diary date is 11-SEP-2026. Corrected. | L21: 46292 | M21: N | N21: One root cause, two checks: raised as one query so the site isn't asked the same thing twice. Correction clears both hits. Closed. | O21: 46293 | P21: Closed | Q21: Data corrected | R21: =L21-J21 -> 6 | S21: =O21-J21 -> 7

Sheet Listing Review
A1: Review ID | B1: Check ID | C1: SUBJID | D1: Finding | E1: Date Reviewed | F1: Reviewer Outcome
A2: LR-01 | B2: SZ06 | C2: 01001004 | D2: Baseline: total 5 < 8; weeks 1-4 = 1 < 3 | E2: 24-MAR-2026 | F2: Subject was not randomized (screen failure). The listing worked as intended. No query.
A3: LR-02 | B3: SZ06 | C3: 01003003 | D3: Baseline: seizure-free run of 33 days > 25 | E3: 16-MAR-2026 | F3: Subject was not randomized (screen failure). The listing worked as intended. No query.
A4: LR-03 | B4: ML01 | C4: 01001005 | D4: Dose reduced; AE start Study Day 6 (Week 1) | E4: 20-APR-2026 | F4: Dosing records show the reduction was made at Visit 4 (Study Day 15, Week 3), which is permitted. The AE started in Week 1, but the dose did not change until Week 3. No query, no deviation.
A5: LR-04 | B5: DM04 | C5: — | D5: 0 hits | E5: — | F5: No planted error. Zero hits confirms the check raises no false positives.
A6: LR-05 | B6: AE07 | C6: — | D6: 0 hits | E6: — | F6: No fatal events in the data.
A7: LR-06 | B7: ML02 | C7: 01001002, 01002005 | D7: 2 serious AEs in the study data (Wrist fracture; Pneumonia) | E7: Pending | F7: Reconciliation against the safety database is pending. It needs a safety-database extract, which is not part of this package.

Sheet Audit Trail
A1: Audit ID | B1: Date of Change | C1: SUBJID | D1: Form | E1: Record | F1: Field | G1: Old Value | H1: New Value | I1: Changed By | J1: Reason (Query)
A2: AT-001 | B2: 46051 | C2: 01001002 | D2: DM | E2: Demographics | F2: CHILDPOT | G2: (blank) | H2: N | I2: Site 001 coordinator | J2: QRY-001: Subject is post-menopausal per medical history documented at Visit 1. Entered N.
A3: AT-002 | B3: 46060 | C3: 01003005 | D3: DM | E3: Demographics | F3: SITEID | G3: 002 | H3: 003 | I3: Site 003 coordinator | J3: QRY-002: Coordinator covers sites 002 and 003 and selected the wrong site. Site number corrected to 003.
A4: AT-003 | B4: 46071 | C4: 01003001 | D4: AE | E4: AESPID 1: Headache | F4: Whole record | G4: Active record | H4: (deleted) | I4: Site 003 coordinator | J4: QRY-003: Headache began before consent and did not worsen afterward. Recorded in medical history; AE deleted per investigator.
A5: AT-004 | B5: 46075 | C5: 01002006 | D5: DM | E5: Demographics | F5: BRTHDAT | G5: 28-OCT-1952 | H5: 28-OCT-1982 | I5: Site 002 coordinator | J5: QRY-004: Verified against the copy of the subject's driver's license in the subject file. Birth year was mistyped; DOB corrected to 28-OCT-1982.
A6: AT-005 | B6: 46075 | C6: 01002006 | D6: DM | E6: Demographics | F6: AGE | G6: 73 | H6: 43 | I6: System (derived) | J6: QRY-004: Verified against the copy of the subject's driver's license in the subject file. Birth year was mistyped; DOB corrected to 28-OCT-1982.
A7: AT-006 | B7: 46115 | C7: 01001003 | D7: AE | E7: AESPID 1: Nausea | F7: AEREL | G7: POSSIBLE | H7: UNRELATED | I7: Site 001 coordinator | J7: QRY-006: Investigator reviewed: nausea started during baseline, before any study drug. Relationship changed to Unrelated.
A8: AT-007 | B8: 46116 | C8: 01003002 | D8: DM | E8: Demographics | F8: EXSTDAT | G8: 12-MAR-2026 | H8: 10-MAR-2026 | I8: Site 003 coordinator | J8: QRY-007: Date was copied from the dosing card label. Subject's dosing log shows the first dose the morning after randomization. Corrected.
A9: AT-008 | B9: 46134 | C9: 01003001 | D9: SZ | E9: SZDAT 29-MAR-2026 | F9: Whole record | G9: Duplicate record | H9: (deleted) | I9: Site 003 coordinator | J9: QRY-008: Diary page was entered twice after a system time-out. Duplicate deleted.
A10: AT-009 | B10: 46144 | C10: 01001001 | D10: AE | E10: AESPID 1: Headache | F10: AEENDAT | G10: 06-APR-2025 | H10: 06-APR-2026 | I10: Site 001 coordinator | J10: QRY-010: End date year was mistyped. Correct end date is 06-APR-2026. Corrected.
A11: AT-010 | B11: 46152 | C11: 01002004 | D11: SZ | E11: SZDAT 21-APR-2026 | F11: SZSPM, SZSPNM, SZCP, SZSG | G11: 0, 0, 0, 0 | H11: (blank) | I11: Site 002 coordinator | J11: QRY-011: Diary page for this date is blank. Zeros removed; 'diary data recorded' remains No.
A12: AT-011 | B12: 46195 | C12: 01002001 | D12: AE | E12: AESPID 2: Fatigue | F12: AEONGO | G12: Y | H12: N | I12: Site 002 coordinator | J12: QRY-012: Event resolved on 24-MAY-2026; 'ongoing' was never updated. Changed to No.
A13: AT-012 | B13: 46199 | C13: 01001007 | D13: SZ | E13: SZDAT 03-JUN-2026 | F13: Whole record | G13: (no record) | H13: SZDIARY Y; SPM 0.0, SPNM 1.0, CP 0.0, SG 0.0 | I13: Site 001 coordinator | J13: QRY-014: One diary page (5 days) was not transcribed. Entered from the source diary.
... A22: AT-021 | B22: 46292 | C22: 01002007 | D22: SZ | E22: Diary record | F22: SZDAT | G22: 11-OCT-2026 | H22: 11-SEP-2026 | I22: Site 002 coordinator | J22: QRY-020: Month was mistyped. Diary date is 11-SEP-2026. Corrected.

Sheet Re-run Results
A1: Check ID | B1: SUBJID | C1: Form | D1: Record | E1: Value Found | F1: Previously Reviewed As | G1: Re-run Status
A2: AE06 | B2: 01002004 | C2: AE | D2: AESPID 3: Increased seizure frequency | E2: Increased seizure frequency | F2: QRY-013 (Confirmed correct) | G2: Previously closed. Not re-queried.
A3: DM05 | B3: 01002002 | C3: DM | D3: Demographics | E3: 61 days | F3: QRY-005 (Confirmed correct) | G3: Previously closed. Not re-queried.
A4: ML01 | B4: 01001005 | C4: AE | D4: AESPID 1: Somnolence | E4: Dose reduced; AE start Study Day 6 | F4: LR-03 (Listing review) | G4: Previously closed. Not re-queried.
A5: SZ04 | B5: 01001005 | C5: SZ | D5: SZDAT 09-JUL-2026 | E5: 22 | F5: QRY-019 (Confirmed correct) | G5: Previously closed. Not re-queried.
A6: SZ06 | B6: 01001004 | C6: SZ | D6: Baseline period | E6: total 5 < 8; weeks 1-4 = 1 < 3 | F6: LR-01 (Screen failure) | G6: Previously closed. Not re-queried.
A7: SZ06 | B7: 01003003 | C7: SZ | D7: Baseline period | E7: seizure-free run of 33 days > 25 | F7: LR-02 (Screen failure) | G7: Previously closed. Not re-queried.
A8: SZ06 | B8: 01003006 | C8: SZ | D8: Baseline period | E8: weeks 1-4 = 2 < 3 | F8: QRY-009 (Escalated) | G8: Previously closed. Not re-queried.
